Traceback (most recent call last):
  File "/home/tai/reposnew/ns-3-allinone/ns-3-dev/.waf-1.8.19-b1fc8f7baef51bd2db4c2971909a568d/waflib/Logs.py", line 84, in emit
    self.flush()
  File "/usr/lib/python2.7/logging/__init__.py", line 845, in flush
    self.stream.flush()
IOError: [Errno 32] Broken pipe
Logged from file Logs.py, line 163
Traceback (most recent call last):
  File "/home/tai/reposnew/ns-3-allinone/ns-3-dev/.waf-1.8.19-b1fc8f7baef51bd2db4c2971909a568d/waflib/Logs.py", line 84, in emit
    self.flush()
  File "/usr/lib/python2.7/logging/__init__.py", line 845, in flush
    self.stream.flush()
IOError: [Errno 32] Broken pipe
Logged from file Logs.py, line 163
Traceback (most recent call last):
  File "/home/tai/reposnew/ns-3-allinone/ns-3-dev/.waf-1.8.19-b1fc8f7baef51bd2db4c2971909a568d/waflib/Logs.py", line 84, in emit
    self.flush()
  File "/usr/lib/python2.7/logging/__init__.py", line 845, in flush
    self.stream.flush()
IOError: [Errno 32] Broken pipe
Logged from file Logs.py, line 163
Traceback (most recent call last):
  File "/home/tai/reposnew/ns-3-allinone/ns-3-dev/.waf-1.8.19-b1fc8f7baef51bd2db4c2971909a568d/waflib/Logs.py", line 84, in emit
    self.flush()
  File "/usr/lib/python2.7/logging/__init__.py", line 845, in flush
    self.stream.flush()
IOError: [Errno 32] Broken pipe
UdpEchoServerApplication:UdpEchoServer(0x55664b4a52b0)
UdpEchoServerApplication:StartApplication(0x55664b4a52b0)
+2.000000000s 7 UdpEchoClientApplication:Send(): [INFO ] At time 2s client sent 1024 bytes to 10.1.2.4 port 9
UdpEchoServerApplication:HandleRead(0x55664b4a52b0, 0x55664b3ea840)
At time 2.01794s server received 1024 bytes from 10.1.3.3 port 49153
Echoing packet
At time 2.01794s server sent 1024 bytes to 10.1.3.3 port 49153
+2.033713014s 7 UdpEchoClientApplication:HandleRead(): [INFO ] At time 2.03371s client received 1024 bytes from 10.1.2.4 port 9
UdpEchoServerApplication:DoDispose(0x55664b4a52b0)
UdpEchoServerApplication:~UdpEchoServer(0x55664b4a52b0)
